<?xml version="1.0" ?>
<!-- =================================================================================== -->
<!-- |    This document was autogenerated by xacro from complete.xacro                 | -->
<!-- |    EDITING THIS FILE BY HAND IS NOT RECOMMENDED                                 | -->
<!-- =================================================================================== -->
<robot name="assembled_robot">
  <!-- THE ROBOT -->
  <link name="world"/>
  
  <joint name="world_joint" type="fixed">
    <parent link="world"/>
    <child link="gripper_base"/>
    <origin rpy="0.0 0.0 0.0" xyz="0.0 0.0 0.0"/>
  </joint>
  
  <link name="gripper_base">
    <inertial>
      <mass value="0.5"/>
      <origin xyz="0 0 0.0412"/>
      <inertia ixx="0.000584375" ixy="0" ixz="0" iyy="0.000584375" iyz="0" izz="0.0004"/>
    </inertial>
    <visual>
      <origin rpy="0 -1.5708 0" xyz="0 0 0"/>
      <geometry>
        <mesh filename="package://robotiq_2f_model/model/meshes/2f85/visual/base.dae"/>
      </geometry>
    </visual>
    <collision>
      <origin rpy="0 0 0" xyz="0 0 0.015"/>
      <geometry>
        <cylinder length="0.045" radius="0.04"/>
      </geometry>
    </collision>
    <collision>
      <origin rpy="0 0 0" xyz="0 0 0.06"/>
      <geometry>
        <box size="0.03 0.03 0.06"/>
      </geometry>
    </collision>
  </link>
  <!-- right finger -->
  <joint name="gripper_right_driver_joint" type="revolute">
    <origin rpy="0 0 0" xyz="0 0.0306011 0.054904"/>
    <parent link="gripper_base"/>
    <child link="gripper_right_driver"/>
    <axis xyz="1 0 0"/>
    <limit effort="60" lower="0.0" upper="0.8726644444444445" velocity="1.919861777777778"/>
  </joint>
  <link name="gripper_right_driver">
    <inertial>
      <mass value="0.1"/>
      <origin rpy="0 0 0" xyz="0 0.02 0"/>
      <inertia ixx="0.000016666666666666666" ixy="0" ixz="0" iyy="0.000006666666666666667" iyz="0" izz="0.000016666666666666666"/>
    </inertial>
    <visual>
      <geometry>
        <mesh filename="package://robotiq_2f_model/model/meshes/2f85/visual/driver.dae" scale="0.001 0.001 0.001"/>
      </geometry>
    </visual>
    <collision>
      <origin rpy="-0.1 0 0" xyz="0 0.01 0"/>
      <geometry>
        <box size="0.002 0.004 0.002"/>
      </geometry>
    </collision>
  </link>
  <joint name="gripper_right_coupler_joint" type="fixed">
    <origin rpy="0 0 0" xyz="0 0.0315 -0.0041"/>
    <parent link="gripper_right_driver"/>
    <child link="gripper_right_coupler"/>
  </joint>
  <link name="gripper_right_coupler">
    <inertial>
      <mass value="0.1"/>
      <origin rpy="-1.7 0 0" xyz="0 0.0 0.025"/>
      <inertia ixx="0.000038541666666666675" ixy="0" ixz="0" iyy="0.000010833333333333334" iyz="0" izz="0.00004270833333333334"/>
    </inertial>
    <visual>
      <geometry>
        <mesh filename="package://robotiq_2f_model/model/meshes/2f85/visual/coupler.dae" scale="0.001 0.001 0.001"/>
      </geometry>
    </visual>
    <collision>
      <origin rpy="-1.7 0 0" xyz="0 0.0 0.025"/>
      <geometry>
        <box size="0.03 0.065 0.02"/>
      </geometry>
    </collision>
  </link>
  <joint name="gripper_right_follower_joint" type="revolute">
    <origin rpy="0 0 0" xyz="0 0.0061 0.0471"/>
    <parent link="gripper_right_coupler"/>
    <child link="gripper_right_follower"/>
    <axis xyz="1 0 0"/>
    <limit effort="176" lower="-2.9670591111111113" upper="2.9670591111111113" velocity="1.919861777777778"/>
    <mimic joint="gripper_right_driver_joint" multiplier="-1"/>
  </joint>
  <link name="gripper_right_follower">
    <inertial>
      <mass value="0.1"/>
      <origin xyz="0 -0.018 0.022"/>
      <inertia ixx="0.000021075" ixy="0" ixz="0" iyy="0.000022533333333333336" iyz="0" izz="0.000005208333333333333"/>
    </inertial>
    <visual>
      <geometry>
        <mesh filename="package://robotiq_2f_model/model/meshes/2f85/visual/follower.dae" scale="0.001 0.001 0.001"/>
      </geometry>
    </visual>
    <collision>
      <origin rpy="0 0 0" xyz="0 -0.01 0.022"/>
      <geometry>
        <box size="0.002 0.0015 0.0048"/>
      </geometry>
    </collision>
  </link>
  <joint name="gripper_right_pad_joint" type="fixed">
    <parent link="gripper_right_follower"/>
    <child link="gripper_right_pad"/>
  </joint>
  <link name="gripper_right_pad">
    <inertial>
      <mass value="0.1"/>
      <origin xyz="0 -0.022 0.031"/>
      <inertia ixx="0.000011333333333333332" ixy="0" ixz="0" iyy="0.000014133333333333331" iyz="0" izz="0.0000038666666666666663"/>
    </inertial>
    <visual>
      <geometry>
        <mesh filename="package://robotiq_2f_model/model/meshes/2f85/visual/pad.dae" scale="0.001 0.001 0.001"/>
      </geometry>
    </visual>
    <collision>
      <origin rpy="0 0 0" xyz="0 -0.022 0.031"/>
      <geometry>
        <box size="0.02 0.008 0.036"/>
      </geometry>
    </collision>
  </link>
  <joint name="gripper_right_spring_link_joint" type="revolute">
    <origin rpy="0 0 0" xyz="0 0.012 0.0614"/>
    <parent link="gripper_base"/>
    <child link="gripper_right_spring_link"/>
    <axis xyz="1 0 0"/>
    <limit effort="176" lower="-2.9670591111111113" upper="2.9670591111111113" velocity="1.919861777777778"/>
    <mimic joint="gripper_right_driver_joint" multiplier="1"/>
  </joint>
  <link name="gripper_right_spring_link">
    <inertial>
      <mass value="0.1"/>
      <origin rpy="-0.7068 0 0" xyz="0 0.018 0.018"/>
      <inertia ixx="0.000038541666666666675" ixy="0" ixz="0" iyy="0.00004854166666666667" iyz="0" izz="0.000016666666666666666"/>
    </inertial>
    <visual>
      <geometry>
        <mesh filename="package://robotiq_2f_model/model/meshes/2f85/visual/spring_link.dae" scale="0.001 0.001 0.001"/>
      </geometry>
    </visual>
    <collision>
      <origin rpy="-0.7068 0 0" xyz="0 0.025 0.015"/>
      <geometry>
        <box size="0.004 0.002 0.0065"/>
      </geometry>
    </collision>
  </link>
  <!-- left finger -->
  <joint name="gripper_left_driver_joint" type="revolute">
    <origin rpy="0 0 3.141592653589793" xyz="0 -0.0306011 0.054904"/>
    <parent link="gripper_base"/>
    <child link="gripper_left_driver"/>
    <axis xyz="1 0 0"/>
    <limit effort="176" lower="0.0" upper="0.8726644444444445" velocity="1.919861777777778"/>
    <mimic joint="gripper_right_driver_joint" multiplier="1"/>
  </joint>
  <link name="gripper_left_driver">
    <inertial>
      <mass value="0.1"/>
      <origin rpy="0 0 0" xyz="0 0.02 0"/>
      <inertia ixx="0.000016666666666666666" ixy="0" ixz="0" iyy="0.000006666666666666667" iyz="0" izz="0.000016666666666666666"/>
    </inertial>
    <visual>
      <geometry>
        <mesh filename="package://robotiq_2f_model/model/meshes/2f85/visual/driver.dae" scale="0.001 0.001 0.001"/>
      </geometry>
    </visual>
    <collision>
      <origin rpy="-0.1 0 0" xyz="0 0.01 0"/>
      <geometry>
        <box size="0.002 0.004 0.002"/>
      </geometry>
    </collision>
  </link>
  <joint name="gripper_left_coupler_joint" type="fixed">
    <origin rpy="0 0 0" xyz="0 0.0315 -0.0041"/>
    <parent link="gripper_left_driver"/>
    <child link="gripper_left_coupler"/>
  </joint>
  <link name="gripper_left_coupler">
    <inertial>
      <mass value="0.1"/>
      <origin rpy="-1.7 0 0" xyz="0 0.0 0.025"/>
      <inertia ixx="0.000038541666666666675" ixy="0" ixz="0" iyy="0.000010833333333333334" iyz="0" izz="0.00004270833333333334"/>
    </inertial>
    <visual>
      <geometry>
        <mesh filename="package://robotiq_2f_model/model/meshes/2f85/visual/coupler.dae" scale="0.001 0.001 0.001"/>
      </geometry>
    </visual>
    <collision>
      <origin rpy="-1.7 0 0" xyz="0 0.0 0.025"/>
      <geometry>
        <box size="0.03 0.065 0.02"/>
      </geometry>
    </collision>
  </link>
  <joint name="gripper_left_follower_joint" type="revolute">
    <origin rpy="0 0 0" xyz="0 0.0061 0.0471"/>
    <parent link="gripper_left_coupler"/>
    <child link="gripper_left_follower"/>
    <axis xyz="1 0 0"/>
    <limit effort="176" lower="-2.9670591111111113" upper="2.9670591111111113" velocity="1.919861777777778"/>
    <mimic joint="gripper_right_driver_joint" multiplier="-1"/>
  </joint>
  <link name="gripper_left_follower">
    <inertial>
      <mass value="0.1"/>
      <origin xyz="0 -0.018 0.022"/>
      <inertia ixx="0.000021075" ixy="0" ixz="0" iyy="0.000022533333333333336" iyz="0" izz="0.000005208333333333333"/>
    </inertial>
    <visual>
      <geometry>
        <mesh filename="package://robotiq_2f_model/model/meshes/2f85/visual/follower.dae" scale="0.001 0.001 0.001"/>
      </geometry>
    </visual>
    <collision>
      <origin rpy="0 0 0" xyz="0 -0.01 0.022"/>
      <geometry>
        <box size="0.002 0.0015 0.0048"/>
      </geometry>
    </collision>
  </link>
  <joint name="gripper_left_pad_joint" type="fixed">
    <parent link="gripper_left_follower"/>
    <child link="gripper_left_pad"/>
  </joint>
  <link name="gripper_left_pad">
    <inertial>
      <mass value="0.1"/>
      <origin xyz="0 -0.022 0.031"/>
      <inertia ixx="0.000011333333333333332" ixy="0" ixz="0" iyy="0.000014133333333333331" iyz="0" izz="0.0000038666666666666663"/>
    </inertial>
    <visual>
      <geometry>
        <mesh filename="package://robotiq_2f_model/model/meshes/2f85/visual/pad.dae" scale="0.001 0.001 0.001"/>
      </geometry>
    </visual>
    <collision>
      <origin rpy="0 0 0" xyz="0 -0.022 0.031"/>
      <geometry>
        <box size="0.02 0.008 0.036"/>
      </geometry>
    </collision>
  </link>
  <joint name="gripper_left_spring_link_joint" type="revolute">
    <origin rpy="0 0 3.141592653589793" xyz="0 -0.012 0.0614"/>
    <parent link="gripper_base"/>
    <child link="gripper_left_spring_link"/>
    <axis xyz="1 0 0"/>
    <limit effort="176" lower="-2.9670591111111113" upper="2.9670591111111113" velocity="1.919861777777778"/>
    <mimic joint="gripper_right_driver_joint" multiplier="1"/>
  </joint>
  <link name="gripper_left_spring_link">
    <inertial>
      <mass value="0.1"/>
      <origin rpy="-0.7068 0 0" xyz="0 0.018 0.018"/>
      <inertia ixx="0.000038541666666666675" ixy="0" ixz="0" iyy="0.00004854166666666667" iyz="0" izz="0.000016666666666666666"/>
    </inertial>
    <visual>
      <geometry>
        <mesh filename="package://robotiq_2f_model/model/meshes/2f85/visual/spring_link.dae" scale="0.001 0.001 0.001"/>
      </geometry>
    </visual>
    <collision>
      <origin rpy="-0.7068 0 0" xyz="0 0.025 0.015"/>
      <geometry>
        <box size="0.004 0.002 0.0065"/>
      </geometry>
    </collision>
  </link>
  <transmission name="gripper_right_driver_trans">
    <type>transmission_interface/SimpleTransmission</type>
    <joint name="gripper_right_driver_joint">
      <hardwareInterface>hardware_interface/PositionJointInterface</hardwareInterface>
    </joint>
    <actuator name="gripper_right_driver_motor">
      <mechanicalReduction>1</mechanicalReduction>
    </actuator>
  </transmission>
  <gazebo>
    <plugin filename="libroboticsgroup_gazebo_mimic_joint_plugin.so" name="gripper_right_follower_joint_plugin">
      <joint>gripper_right_driver_joint</joint>
      <mimicJoint>gripper_right_follower_joint</mimicJoint>
      <multiplier>-1</multiplier>
    </plugin>
    <plugin filename="libroboticsgroup_gazebo_mimic_joint_plugin.so" name="gripper_right_spring_link_joint_plugin">
      <joint>gripper_right_driver_joint</joint>
      <mimicJoint>gripper_right_spring_link_joint</mimicJoint>
      <multiplier>1</multiplier>
    </plugin>
    <plugin filename="libroboticsgroup_gazebo_mimic_joint_plugin.so" name="gripper_left_follower_joint_plugin">
      <joint>gripper_right_driver_joint</joint>
      <mimicJoint>gripper_left_follower_joint</mimicJoint>
      <multiplier>-1</multiplier>
    </plugin>
    <plugin filename="libroboticsgroup_gazebo_mimic_joint_plugin.so" name="gripper_left_spring_link_joint_plugin">
      <joint>gripper_right_driver_joint</joint>
      <mimicJoint>gripper_left_spring_link_joint</mimicJoint>
      <multiplier>1</multiplier>
    </plugin>
    <plugin filename="libroboticsgroup_gazebo_mimic_joint_plugin.so" name="gripper_left_driver_joint_plugin">
      <joint>gripper_right_driver_joint</joint>
      <mimicJoint>gripper_left_driver_joint</mimicJoint>
      <multiplier>1</multiplier>
    </plugin>
  </gazebo>
  
</robot>

